<?xml version="1.0" ?>
<!-- =================================================================================== -->
<!-- |    This document was autogenerated by xacro from split_aloha_rslidar_with_piper.xacro | -->
<!-- |    EDITING THIS FILE BY HAND IS NOT RECOMMENDED                                 | -->
<!-- =================================================================================== -->
<robot name="split_aloha_rslidar_with_piper">
  <link name="base_link">
    <inertial>
      <origin rpy="0 0 0" xyz="-0.0242698272228022 -0.0030308024613212 0.0544267444673498"/>
      <mass value="10"/>
      <inertia ixx="0.1354" ixy="0.0" ixz="0.0" iyy="0.2417" iyz="0.0" izz="0.3085"/>
    </inertial>
    <visual>
      <origin rpy="0 0 0" xyz="0 0 0.0"/>
      <geometry>
        <mesh filename="package://split_aloha_mid_360/meshes/ranger_base.dae" scale="1000 1000 1000"/>
      </geometry>
      <material name="">
        <color rgba="0.792156862745098 0.819607843137255 0.933333333333333 1"/>
      </material>
    </visual>
    <collision>
      <origin rpy="0 0 0" xyz="0 0 -0.1"/>
      <geometry>
        <box size="0.5 0.35 0.2"/>
      </geometry>
    </collision>
  </link>
  <link name="fr_steering_wheel_link">
    <inertial>
      <origin rpy="0 0 0" xyz="1.8493E-05 1.2713E-06 0.043679"/>
      <mass value="1"/>
      <inertia ixx="0.0063625" ixy="-1.0581E-07" ixz="-4.0831E-07" iyy="0.006363" iyz="-3.4944E-08" izz="0.010465"/>
    </inertial>
    <visual>
      <origin rpy="0 0 0" xyz="0 0 0"/>
      <geometry>
        <mesh filename="package://split_aloha_mid_360/meshes/steering_wheel.dae" scale="10 10 10"/>
      </geometry>
      <material name="">
        <color rgba="0.79216 0.81961 0.93333 1"/>
      </material>
    </visual>
    <collision>
      <origin rpy="0 0 0" xyz="0 0 0"/>
      <geometry>
        <!-- <mesh
          filename="package://split_aloha_mid_360/meshes/split_aloha_mid_360_wheel_right.dae" /> -->
        <cylinder length="0.001" radius="0.001"/>
      </geometry>
    </collision>
  </link>
  <joint name="fr_steering_joint" type="revolute">
    <origin rpy="0 0 0" xyz="0.25 -0.19 -0.1"/>
    <parent link="base_link"/>
    <child link="fr_steering_wheel_link"/>
    <axis xyz="0 0 -1"/>
    <limit effort="5" lower="-2.1" upper="2.1" velocity="6.28"/>
  </joint>
  <link name="fr_wheel_link">
    <inertial>
      <mass value="8"/>
      <origin xyz="0 0 0"/>
      <inertia ixx="0.02047" ixy="0.0" ixz="0.0" iyy="0.02047" iyz="0.0" izz="0.0324"/>
    </inertial>
    <visual>
      <origin rpy="3.14 0 0" xyz="0 0 0"/>
      <geometry>
        <mesh filename="package://split_aloha_mid_360/meshes/wheel_v3.dae" scale="10 10 10"/>
      </geometry>
    </visual>
    <collision>
      <origin rpy="1.57 0 0" xyz="0 0 -0.005"/>
      <geometry>
        <cylinder length="0.08" radius="0.09"/>
      </geometry>
      <contact>
        <ode>
          <min_depth>0.001</min_depth>
        </ode>
      </contact>
    </collision>
  </link>
  <joint name="fr_wheel" type="continuous">
    <origin rpy="0 0 0" xyz="0.0 0.0 -0.12"/>
    <parent link="fr_steering_wheel_link"/>
    <child link="fr_wheel_link"/>
    <axis rpy="0 0 0" xyz="0 1 0"/>
  </joint>
  <link name="fl_steering_wheel_link">
    <inertial>
      <origin rpy="0 0 0" xyz="-0.0017956 -9.6304E-08 0.043642"/>
      <mass value="1"/>
      <inertia ixx="0.0063695" ixy="-2.1067E-08" ixz="-0.00016867" iyy="0.006363" iyz="-1.0301E-08" izz="0.010458"/>
    </inertial>
    <visual>
      <origin rpy="0 0 3.14" xyz="0 0 0"/>
      <geometry>
        <mesh filename="package://split_aloha_mid_360/meshes/steering_wheel.dae" scale="10 10 10"/>
      </geometry>
      <material name="">
        <color rgba="0.79216 0.81961 0.93333 1"/>
      </material>
    </visual>
    <collision>
      <origin rpy="0 0 0" xyz="0 0 0"/>
      <geometry>
        <!-- <mesh
          filename="package://split_aloha_mid_360/meshes/split_aloha_mid_360_wheel.dae" /> -->
        <cylinder length="0.001" radius="0.001"/>
      </geometry>
    </collision>
  </link>
  <joint name="fl_steering_joint" type="revolute">
    <origin rpy="0 0 0" xyz="0.25 0.19 -0.1"/>
    <parent link="base_link"/>
    <child link="fl_steering_wheel_link"/>
    <axis xyz="0 0 -1"/>
    <limit effort="5" lower="-2.1" upper="2.1" velocity="6.28"/>
  </joint>
  <link name="fl_wheel_link">
    <inertial>
      <mass value="8"/>
      <origin xyz="0 0 0"/>
      <inertia ixx="0.02047" ixy="0.0" ixz="0.0" iyy="0.02047" iyz="0.0" izz="0.0324"/>
    </inertial>
    <visual>
      <origin rpy="0 0 0" xyz="0 0 0"/>
      <geometry>
        <mesh filename="package://split_aloha_mid_360/meshes/wheel_v3.dae" scale="10 10 10"/>
      </geometry>
    </visual>
    <collision>
      <origin rpy="1.57 0 0" xyz="0 0 -0.005"/>
      <geometry>
        <cylinder length="0.08" radius="0.09"/>
      </geometry>
      <contact>
        <ode>
          <min_depth>0.001</min_depth>
        </ode>
      </contact>
    </collision>
  </link>
  <joint name="fl_wheel" type="continuous">
    <origin rpy="0 0 0" xyz="0.0 0.0 -0.12"/>
    <parent link="fl_steering_wheel_link"/>
    <child link="fl_wheel_link"/>
    <axis rpy="0 0 0" xyz="0 1 0"/>
  </joint>
  <link name="rl_steering_wheel_link">
    <inertial>
      <origin rpy="0 0 0" xyz="-0.00017093 6.1255E-08 0.043678"/>
      <mass value="1"/>
      <inertia ixx="0.0063627" ixy="-2.1069E-08" ixz="-1.587E-05" iyy="0.006363" iyz="9.3201E-09" izz="0.010465"/>
    </inertial>
    <visual>
      <origin rpy="0 0 3.14" xyz="0 0 0"/>
      <geometry>
        <mesh filename="package://split_aloha_mid_360/meshes/steering_wheel.dae" scale="10 10 10"/>
      </geometry>
      <material name="">
        <color rgba="0.79216 0.81961 0.93333 1"/>
      </material>
    </visual>
    <collision>
      <origin rpy="0 0 0" xyz="0 0 0"/>
      <geometry>
        <!-- <mesh
          filename="package://split_aloha_mid_360/meshes/split_aloha_mid_360_wheel_right.dae" /> -->
        <cylinder length="0.001" radius="0.001"/>
      </geometry>
    </collision>
  </link>
  <joint name="rl_steering_joint" type="revolute">
    <origin rpy="0 0 0" xyz="-0.25 0.19 -0.1"/>
    <parent link="base_link"/>
    <child link="rl_steering_wheel_link"/>
    <axis xyz="0 0 -1"/>
    <limit effort="5" lower="-2.1" upper="2.1" velocity="6.28"/>
  </joint>
  <link name="rl_wheel_link">
    <inertial>
      <mass value="8"/>
      <origin xyz="0 0 0"/>
      <inertia ixx="0.02047" ixy="0.0" ixz="0.0" iyy="0.02047" iyz="0.0" izz="0.0324"/>
    </inertial>
    <visual>
      <origin rpy="0 0 0" xyz="0 0 0"/>
      <geometry>
        <mesh filename="package://split_aloha_mid_360/meshes/wheel_v3.dae" scale="10 10 10"/>
      </geometry>
    </visual>
    <collision>
      <origin rpy="1.57 0 0" xyz="0.00 0.00 -0.005"/>
      <geometry>
        <cylinder length="0.08" radius="0.09"/>
      </geometry>
      <contact>
        <ode>
          <min_depth>0.001</min_depth>
        </ode>
      </contact>
    </collision>
  </link>
  <joint name="rl_wheel" type="continuous">
    <origin rpy="0 0 0" xyz="0.0 0.0 -0.12 "/>
    <parent link="rl_steering_wheel_link"/>
    <child link="rl_wheel_link"/>
    <axis rpy="0 0 0" xyz="0 1 0"/>
  </joint>
  <link name="rr_steering_wheel_link">
    <inertial>
      <origin xyz="0.0 0.0 0.0"/>
      <mass value="1"/>
      <inertia ixx="0.01" ixy="0.0" ixz="0.0" iyy="0.01" iyz="0.0" izz="0.01"/>
    </inertial>
    <visual>
      <origin rpy="0 0 0" xyz="0 0 0"/>
      <geometry>
        <mesh filename="package://split_aloha_mid_360/meshes/steering_wheel.dae" scale="10 10 10"/>
      </geometry>
    </visual>
    <collision>
      <origin rpy="0 0 0" xyz="0 0 0"/>
      <geometry>
        <cylinder length="0.001" radius="0.001"/>
      </geometry>
    </collision>
  </link>
  <joint name="rr_steering_joint" type="revolute">
    <origin rpy="0 0 0" xyz="-0.23 -0.206 -0.1"/>
    <parent link="base_link"/>
    <child link="rr_steering_wheel_link"/>
    <axis rpy="0 0 0" xyz="0 0 -1"/>
    <limit effort="5" lower="-2.1" upper="2.1" velocity="6.28"/>
  </joint>
  <link name="rr_wheel_link">
    <inertial>
      <mass value="8"/>
      <origin xyz="0 0 0"/>
      <inertia ixx="0.02047" ixy="0.0" ixz="0.0" iyy="0.02047" iyz="0.0" izz="0.0324"/>
    </inertial>
    <visual>
      <origin rpy="3.14 0 0" xyz="0.0 0.0 0.0"/>
      <geometry>
        <mesh filename="package://split_aloha_mid_360/meshes/wheel_v3.dae" scale="10 10 10"/>
      </geometry>
    </visual>
    <collision>
      <origin rpy="1.57 0 0" xyz="0.00 0 -0.005"/>
      <geometry>
        <cylinder length="0.08" radius="0.09"/>
      </geometry>
      <contact>
        <ode>
          <min_depth>0.001</min_depth>
        </ode>
      </contact>
    </collision>
  </link>
  <joint name="rr_wheel" type="continuous">
    <origin rpy="0 0 0" xyz="0.0 0.0 -0.12 "/>
    <parent link="rr_steering_wheel_link"/>
    <child link="rr_wheel_link"/>
    <axis rpy="0 0 0" xyz="0 1 0"/>
  </joint>
  
  <link name="box_link">
    <inertial>
      <origin rpy="0 0 0" xyz="0.10921 -0.0087718 0.52779"/>
      <mass value="27.261"/>
      <inertia ixx="1.8122" ixy="4.558E-05" ixz="0.014722" iyy="1.7779" iyz="-4.0693E-05" izz="0.28053"/>
    </inertial>
    <visual>
      <origin rpy="0 0 0" xyz="0 0 0"/>
      <geometry>
        <mesh filename="package://split_aloha_mid_360/meshes/box_link.dae" scale="1000 1000 1000"/>
      </geometry>
      <material name="">
        <color rgba="1 1 1 1"/>
      </material>
    </visual>
    <collision>
      <origin rpy="0 0 0" xyz="0 0 0"/>
      <geometry>
        <mesh filename="package://split_aloha_mid_360/meshes/box_link.dae" scale="1000 1000 1000"/>
      </geometry>
    </collision>
  </link>
  <joint name="box_joint" type="fixed">
    <origin rpy="0 0 0" xyz="0 0 0"/>
    <parent link="base_link"/>
    <child link="box_link"/>
    <axis xyz="0 0 0"/>
  </joint>
  <link name="front_camera_link">
    <inertial>
      <origin rpy="0 0 0" xyz="-0.011443 0.0003607 -0.0012124"/>
      <mass value="0.020053"/>
      <inertia ixx="1.1182E-05" ixy="2.589E-09" ixz="5.6552E-08" iyy="2.2729E-06" iyz="-6.7447E-07" izz="1.0081E-05"/>
    </inertial>
    <visual>
      <origin rpy="0 0 0" xyz="0 0 0"/>
      <geometry>
        <mesh filename="package://split_aloha_mid_360/meshes/front_camera_link.dae" scale="1000 1000 1000"/>
      </geometry>
      <material name="">
        <color rgba="1 1 1 1"/>
      </material>
    </visual>
    <collision>
      <origin rpy="0 0 0" xyz="0 0 0"/>
      <geometry>
        <mesh filename="package://split_aloha_mid_360/meshes/front_camera_link.dae" scale="1000 1000 1000"/>
      </geometry>
    </collision>
  </link>
  <joint name="front_camera_joint" type="fixed">
    <origin rpy="-0.11187 0.6606 -0.0051043" xyz="0.35679 0 0.15819"/>
    <parent link="box_link"/>
    <child link="front_camera_link"/>
    <axis xyz="0 0 0"/>
  </joint>
  <link name="lidar_link">
    <inertial>
      <origin rpy="0 0 0" xyz="-0.0022133 -0.00090659 0.025996"/>
      <mass value="0.048617"/>
      <inertia ixx="1.0358E-05" ixy="9.2377E-09" ixz="-2.6386E-07" iyy="1.0387E-05" iyz="-2.6377E-07" izz="1.7919E-05"/>
    </inertial>
    <visual>
      <origin rpy="0 0 0" xyz="0 0 0"/>
      <geometry>
        <!-- <mesh
          filename="package://split_aloha_mid_360/meshes/lidar_link.dae" scale="1000 1000 1000"/> -->
        <cylinder length="0.1" radius="0.05"/>
      </geometry>
      <material name="">
        <color rgba="1 1 1 1"/>
      </material>
    </visual>
    <collision>
      <origin rpy="0 0 0" xyz="0 0 0"/>
      <geometry>
        <!-- <mesh
          filename="package://split_aloha_mid_360/meshes/lidar_link.dae" scale="1000 1000 1000"/>-->
        <cylinder length="0.05" radius="0.05"/>
      </geometry>
    </collision>
  </link>
  <joint name="lidar_joint" type="fixed">
    <origin rpy="0 0 0" xyz="0.3 0 0.07"/>
    <parent link="box_link"/>
    <child link="lidar_link"/>
    <axis xyz="0 0 0"/>
  </joint>
  <link name="lifting_link">
    <inertial>
      <origin rpy="0 0 0" xyz="0.071327 0.00032985 0.10599"/>
      <mass value="0.47066"/>
      <inertia ixx="0.010952" ixy="-5.2124E-06" ixz="-0.00046317" iyy="0.0018329" iyz="-4.6428E-06" izz="0.010201"/>
    </inertial>
    <visual>
      <origin rpy="0 0 0" xyz="0 0 0"/>
      <geometry>
        <mesh filename="package://split_aloha_mid_360/meshes/lifting_link.dae" scale="1000 1000 1000"/>
      </geometry>
      <material name="">
        <color rgba="1 1 1 1"/>
      </material>
    </visual>
    <collision>
      <origin rpy="0 0 0" xyz="0 0 0"/>
      <geometry>
        <mesh filename="package://split_aloha_mid_360/meshes/lifting_link.dae" scale="1000 1000 1000"/>
      </geometry>
    </collision>
  </link>
  <joint name="lifting_joint" type="prismatic">
    <origin rpy="0 0 0" xyz="0.22448 0 1.1147"/>
    <parent link="box_link"/>
    <child link="lifting_link"/>
    <axis xyz="0 0 1"/>
    <limit effort="100" lower="-0.6" upper="0.0" velocity="10.0"/>
  </joint>
  <link name="top_camera_link">
    <inertial>
      <origin rpy="0 0 0" xyz="-0.011443 2.4833E-05 -0.0012615"/>
      <mass value="0.020053"/>
      <inertia ixx="1.1181E-05" ixy="1.204E-07" ixz="4.9068E-08" iyy="2.2587E-06" iyz="5.7637E-07" izz="1.0097E-05"/>
    </inertial>
    <visual>
      <origin rpy="0 0 0" xyz="0 0 0"/>
      <geometry>
        <mesh filename="package://split_aloha_mid_360/meshes/top_camera_link.dae" scale="1000 1000 1000"/>
      </geometry>
      <material name="">
        <color rgba="1 1 1 1"/>
      </material>
    </visual>
    <collision>
      <origin rpy="0 0 0" xyz="0 0 0"/>
      <geometry>
        <mesh filename="package://split_aloha_mid_360/meshes/top_camera_link.dae" scale="1000 1000 1000"/>
      </geometry>
    </collision>
  </link>
  <joint name="top_camera_joint" type="fixed">
    <origin rpy="0.049713 0.00080758 -0.01623" xyz="0.16194 0 0.29838"/>
    <parent link="lifting_link"/>
    <child link="top_camera_link"/>
    <axis xyz="0 0 0"/>
  </joint>
  <!-- <xacro:include filename="$(find piper_description)/urdf/piper_description_right.xacro"/> -->
  <link name="left/arm_base">
    <inertial>
      <origin rpy="0 0 0" xyz="-0.00979274765955341 1.82905827587138E-06 0.0410100126360189"/>
      <mass value="0.162548567403693"/>
      <inertia ixx="0.000226596924525071" ixy="-7.33972270153965E-08" ixz="2.13249977802622E-06" iyy="0.000269444772561524" iyz="8.15169009611054E-09" izz="0.000222318258878636"/>
    </inertial>
    <visual>
      <origin rpy="0 0 0" xyz="0 0 0"/>
      <geometry>
        <mesh filename="package://piper_description/meshes/dae/base_link.dae"/>
      </geometry>
      <material name="">
        <color rgba="0.792156862745098 0.819607843137255 0.933333333333333 1"/>
      </material>
    </visual>
    <collision>
      <origin rpy="0 0 0" xyz="0 0 0"/>
      <geometry>
        <mesh filename="package://piper_description/meshes/base_link.STL"/>
      </geometry>
    </collision>
  </link>
  <link name="left/link1">
    <inertial>
      <origin rpy="0 0 0" xyz="0.00131676031927024 0.000310288842008612 -0.00922874512303437"/>
      <mass value="0.0978679932242825"/>
      <inertia ixx="7.76684558296782E-05" ixy="1.09084650459924E-07" ixz="-1.9748053243241E-06" iyy="9.24967780161547E-05" iyz="9.91284646834582E-07" izz="8.24589062407807E-05"/>
    </inertial>
    <visual>
      <origin rpy="0 0 0" xyz="0 0 0"/>
      <geometry>
        <mesh filename="package://piper_description/meshes/dae/link1.dae"/>
      </geometry>
      <material name="">
        <color rgba="0.792156862745098 0.819607843137255 0.933333333333333 1"/>
      </material>
    </visual>
    <collision>
      <origin rpy="0 0 1.5708" xyz="0 0 0"/>
      <geometry>
        <mesh filename="package://piper_description/meshes/link1.STL"/>
      </geometry>
    </collision>
  </link>
  <joint name="left/joint1" type="revolute">
    <origin rpy="0 0 -1.5708" xyz="0 0 0.123"/>
    <parent link="left/arm_base"/>
    <child link="left/link1"/>
    <axis xyz="0 0 1"/>
    <limit effort="100" lower="-2.618" upper="2.618" velocity="3"/>
  </joint>
  <link name="left/link2">
    <inertial>
      <origin rpy="0 0 0" xyz="0.148793602378802 -0.00242026983944119 0.00175154638467948"/>
      <mass value="0.290888938633388"/>
      <inertia ixx="0.000148959640166183" ixy="-7.37750384371657E-05" ixz="-9.68688405196236E-07" iyy="0.00172800946632652" iyz="-1.09692225564224E-06" izz="0.0017754628344594"/>
    </inertial>
    <visual>
      <origin rpy="0 0 0" xyz="0 0 0"/>
      <geometry>
        <mesh filename="package://piper_description/meshes/dae/link2.dae"/>
      </geometry>
      <material name="">
        <color rgba="0.792156862745098 0.819607843137255 0.933333333333333 1"/>
      </material>
    </visual>
    <collision>
      <origin rpy="0 0 0.1" xyz="0 0 0"/>
      <geometry>
        <mesh filename="package://piper_description/meshes/link2.STL"/>
      </geometry>
    </collision>
  </link>
  <joint name="left/joint2" type="revolute">
    <origin rpy="1.5708 -0.034907 -1.5708" xyz="0 0 0"/>
    <parent link="left/link1"/>
    <child link="left/link2"/>
    <axis xyz="0 0 1"/>
    <limit effort="100" lower="0" upper="3.14" velocity="3"/>
  </joint>
  <link name="left/link3">
    <inertial>
      <origin rpy="0 0 0" xyz="-0.0996835215213704 0.0349477226691318 0.000508025815507312"/>
      <mass value="0.290847697793211"/>
      <inertia ixx="0.000107879011637167" ixy="2.92669521203626E-05" ixz="6.825922326238E-07" iyy="0.000214751671792086" iyz="-7.78469047878196E-07" izz="0.000241923439340319"/>
    </inertial>
    <visual>
      <origin rpy="0 0 0" xyz="0 0 0"/>
      <geometry>
        <mesh filename="package://piper_description/meshes/dae/link3.dae"/>
      </geometry>
      <material name="">
        <color rgba="0.792156862745098 0.819607843137255 0.933333333333333 1"/>
      </material>
    </visual>
    <collision>
      <origin rpy="0 0 -1.75" xyz="0 0 0"/>
      <geometry>
        <mesh filename="package://piper_description/meshes/link3.STL"/>
      </geometry>
    </collision>
  </link>
  <joint name="left/joint3" type="revolute">
    <origin rpy="0 0 0.06604341" xyz="0.28358 0.028726 0"/>
    <parent link="left/link2"/>
    <child link="left/link3"/>
    <axis xyz="0 0 1"/>
    <limit effort="100" lower="-2.697" upper="0" velocity="3"/>
  </joint>
  <link name="left/link4">
    <inertial>
      <origin rpy="0 0 0" xyz="0.000276464622387979 -0.00102803669324875 -0.00472830700561663"/>
      <mass value="0.127087348341362"/>
      <inertia ixx="3.82011730423416E-05" ixy="-4.92358350897513E-08" ixz="4.89589432973119E-08" iyy="4.87048555222578E-05" iyz="6.70802942500512E-08" izz="4.10592077565559E-05"/>
    </inertial>
    <visual>
      <origin rpy="0 0 0" xyz="0 0 0"/>
      <geometry>
        <mesh filename="package://piper_description/meshes/dae/link4.dae"/>
      </geometry>
      <material name="">
        <color rgba="0.792156862745098 0.819607843137255 0.933333333333333 1"/>
      </material>
    </visual>
    <collision>
      <origin rpy="0 0 0" xyz="0 0 0"/>
      <geometry>
        <mesh filename="package://piper_description/meshes/link4.STL"/>
      </geometry>
    </collision>
  </link>
  <joint name="left/joint4" type="revolute">
    <origin rpy="-1.5708 0 1.3826" xyz="-0.24221 0.068514 0"/>
    <parent link="left/link3"/>
    <child link="left/link4"/>
    <axis xyz="0 0 1"/>
    <limit effort="100" lower="-1.832" upper="1.832" velocity="3"/>
  </joint>
  <link name="left/link5">
    <inertial>
      <origin rpy="0 0 0" xyz="8.82262433516967E-05 0.0566829014808256 -0.00196119720482461"/>
      <mass value="0.144711242639457"/>
      <inertia ixx="4.39644313662493E-05" ixy="-3.59259686444846E-08" ixz="-1.89747741386183E-08" iyy="5.63173920951307E-05" iyz="-2.1540716689785E-07" izz="4.88713664675268E-05"/>
    </inertial>
    <visual>
      <origin rpy="0 0 0" xyz="0 0 0"/>
      <geometry>
        <mesh filename="package://piper_description/meshes/dae/link5.dae"/>
      </geometry>
      <material name="">
        <color rgba="0.792156862745098 0.819607843137255 0.933333333333333 1"/>
      </material>
    </visual>
    <collision>
      <origin rpy="0 0 -3.14" xyz="0 0 0"/>
      <geometry>
        <mesh filename="package://piper_description/meshes/link5.STL"/>
      </geometry>
    </collision>
  </link>
  <joint name="left/joint5" type="revolute">
    <origin rpy="1.5708 0 0" xyz="0 0 0"/>
    <parent link="left/link4"/>
    <child link="left/link5"/>
    <axis xyz="0 0 1"/>
    <limit effort="100" lower="-1.22" upper="1.22" velocity="3"/>
  </joint>
  <link name="left/link6">
    <inertial>
      <origin rpy="0 0 0" xyz="0.00103120214523473 0.0121761387587524 0.0315480874960164"/>
      <mass value="0.195187143240719"/>
      <inertia ixx="6.43790256535539E-05" ixy="-1.2366166157046E-06" ixz="1.97664606328472E-07" iyy="0.000126146396374301" iyz="2.41157078516408E-06" izz="0.000154087076816444"/>
    </inertial>
    <visual>
      <origin rpy="-1.57 0 0" xyz="-0.002 -0.008 0"/>
      <geometry>
        <mesh filename="package://piper_description/meshes/dae/camera_v3.dae"/>
      </geometry>
      <material name="">
        <color rgba="0.792156862745098 0.819607843137255 0.933333333333333 1"/>
      </material>
    </visual>
    <collision>
      <origin rpy="-1.57 0 0" xyz="-0.002 -0.008 0"/>
      <geometry>
        <mesh filename="package://piper_description/meshes/dae/camera_v3.dae"/>
      </geometry>
    </collision>
  </link>
  <joint name="left/joint6" type="revolute">
    <origin rpy="-1.5708 -1.5708 0" xyz="0 0.091 0.0014165"/>
    <parent link="left/link5"/>
    <child link="left/link6"/>
    <axis xyz="0 0 1"/>
    <limit effort="100" lower="-3.14" upper="3.14" velocity="3"/>
  </joint>
  <link name="left/link7">
    <inertial>
      <origin rpy="0 0 0" xyz="-0.000277778383727112 -0.0467673043650824 -0.00921029491873201"/>
      <mass value="0.02648229234527"/>
      <inertia ixx="9.99787479924589E-06" ixy="-1.57548495096104E-07" ixz="-2.71342775003487E-08" iyy="6.1795212293655E-06" iyz="-1.58939803580081E-06" izz="1.42102717246564E-05"/>
    </inertial>
    <visual>
      <origin rpy="0 0 0" xyz="0 0 0"/>
      <geometry>
        <mesh filename="package://piper_description/meshes/dae/link7.dae"/>
      </geometry>
      <material name="">
        <color rgba="0.792156862745098 0.819607843137255 0.933333333333333 1"/>
      </material>
    </visual>
    <collision>
      <origin rpy="0 3.14 0" xyz="-0.001 0 0.0003"/>
      <geometry>
        <mesh filename="package://piper_description/meshes/link7.STL"/>
      </geometry>
    </collision>
  </link>
  <joint name="left/joint7" type="prismatic">
    <origin rpy="1.5708 0 1.5708" xyz="0 0 0.13503"/>
    <parent link="left/link6"/>
    <child link="left/link7"/>
    <axis xyz="0 0 -1"/>
    <limit effort="10" lower="0" upper="0.05" velocity="1"/>
  </joint>
  <link name="left/link8">
    <inertial>
      <origin rpy="0 0 0" xyz="0.000277816920932317 0.0467673824063769 -0.00921030054508036"/>
      <mass value="0.0264822021416248"/>
      <inertia ixx="9.99779119357223E-06" ixy="-1.57542283433504E-07" ixz="2.71367446701359E-08" iyy="6.17952441557932E-06" iyz="1.58939319453383E-06" izz="1.4210192754512E-05"/>
    </inertial>
    <visual>
      <origin rpy="0 0 0" xyz="0 0 0"/>
      <geometry>
        <mesh filename="package://piper_description/meshes/dae/link8.dae"/>
      </geometry>
      <material name="">
        <color rgba="0.792156862745098 0.819607843137255 0.933333333333333 1"/>
      </material>
    </visual>
    <collision>
      <origin rpy="3.14 0 0" xyz="-0.001 0 0.0003"/>
      <geometry>
        <mesh filename="package://piper_description/meshes/link8.STL"/>
      </geometry>
    </collision>
  </link>
  <joint name="left/joint8" type="prismatic">
    <origin rpy="-1.5708 0 1.5708" xyz="0 0 0.13503"/>
    <parent link="left/link6"/>
    <child link="left/link8"/>
    <axis xyz="0 0 1"/>
    <limit effort="10" lower="-0.05" upper="0" velocity="1"/>
  </joint>
  <link name="right/arm_base">
    <inertial>
      <origin rpy="0 0 0" xyz="-0.00979274765955341 1.82905827587138E-06 0.0410100126360189"/>
      <mass value="0.162548567403693"/>
      <inertia ixx="0.000226596924525071" ixy="-7.33972270153965E-08" ixz="2.13249977802622E-06" iyy="0.000269444772561524" iyz="8.15169009611054E-09" izz="0.000222318258878636"/>
    </inertial>
    <visual>
      <origin rpy="0 0 0" xyz="0 0 0"/>
      <geometry>
        <mesh filename="package://piper_description/meshes/dae/base_link.dae"/>
      </geometry>
      <material name="">
        <color rgba="0.792156862745098 0.819607843137255 0.933333333333333 1"/>
      </material>
    </visual>
    <collision>
      <origin rpy="0 0 0" xyz="0 0 0"/>
      <geometry>
        <mesh filename="package://piper_description/meshes/base_link.STL"/>
      </geometry>
    </collision>
  </link>
  <link name="right/link1">
    <inertial>
      <origin rpy="0 0 0" xyz="0.00131676031927024 0.000310288842008612 -0.00922874512303437"/>
      <mass value="0.0978679932242825"/>
      <inertia ixx="7.76684558296782E-05" ixy="1.09084650459924E-07" ixz="-1.9748053243241E-06" iyy="9.24967780161547E-05" iyz="9.91284646834582E-07" izz="8.24589062407807E-05"/>
    </inertial>
    <visual>
      <origin rpy="0 0 0" xyz="0 0 0"/>
      <geometry>
        <mesh filename="package://piper_description/meshes/dae/link1.dae"/>
      </geometry>
      <material name="">
        <color rgba="0.792156862745098 0.819607843137255 0.933333333333333 1"/>
      </material>
    </visual>
    <collision>
      <origin rpy="0 0 1.5708" xyz="0 0 0"/>
      <geometry>
        <mesh filename="package://piper_description/meshes/link1.STL"/>
      </geometry>
    </collision>
  </link>
  <joint name="right/joint1" type="revolute">
    <origin rpy="0 0 -1.5708" xyz="0 0 0.123"/>
    <parent link="right/arm_base"/>
    <child link="right/link1"/>
    <axis xyz="0 0 1"/>
    <limit effort="100" lower="-2.618" upper="2.618" velocity="3"/>
  </joint>
  <link name="right/link2">
    <inertial>
      <origin rpy="0 0 0" xyz="0.148793602378802 -0.00242026983944119 0.00175154638467948"/>
      <mass value="0.290888938633388"/>
      <inertia ixx="0.000148959640166183" ixy="-7.37750384371657E-05" ixz="-9.68688405196236E-07" iyy="0.00172800946632652" iyz="-1.09692225564224E-06" izz="0.0017754628344594"/>
    </inertial>
    <visual>
      <origin rpy="0 0 0" xyz="0 0 0"/>
      <geometry>
        <mesh filename="package://piper_description/meshes/dae/link2.dae"/>
      </geometry>
      <material name="">
        <color rgba="0.792156862745098 0.819607843137255 0.933333333333333 1"/>
      </material>
    </visual>
    <collision>
      <origin rpy="0 0 0.1" xyz="0 0 0"/>
      <geometry>
        <mesh filename="package://piper_description/meshes/link2.STL"/>
      </geometry>
    </collision>
  </link>
  <joint name="right/joint2" type="revolute">
    <origin rpy="1.5708 -0.034907 -1.5708" xyz="0 0 0"/>
    <parent link="right/link1"/>
    <child link="right/link2"/>
    <axis xyz="0 0 1"/>
    <limit effort="100" lower="0" upper="3.14" velocity="3"/>
  </joint>
  <link name="right/link3">
    <inertial>
      <origin rpy="0 0 0" xyz="-0.0996835215213704 0.0349477226691318 0.000508025815507312"/>
      <mass value="0.290847697793211"/>
      <inertia ixx="0.000107879011637167" ixy="2.92669521203626E-05" ixz="6.825922326238E-07" iyy="0.000214751671792086" iyz="-7.78469047878196E-07" izz="0.000241923439340319"/>
    </inertial>
    <visual>
      <origin rpy="0 0 0" xyz="0 0 0"/>
      <geometry>
        <mesh filename="package://piper_description/meshes/dae/link3.dae"/>
      </geometry>
      <material name="">
        <color rgba="0.792156862745098 0.819607843137255 0.933333333333333 1"/>
      </material>
    </visual>
    <collision>
      <origin rpy="0 0 -1.75" xyz="0 0 0"/>
      <geometry>
        <mesh filename="package://piper_description/meshes/link3.STL"/>
      </geometry>
    </collision>
  </link>
  <joint name="right/joint3" type="revolute">
    <origin rpy="0 0 0.06604341" xyz="0.28358 0.028726 0"/>
    <parent link="right/link2"/>
    <child link="right/link3"/>
    <axis xyz="0 0 1"/>
    <limit effort="100" lower="-2.697" upper="0" velocity="3"/>
  </joint>
  <link name="right/link4">
    <inertial>
      <origin rpy="0 0 0" xyz="0.000276464622387979 -0.00102803669324875 -0.00472830700561663"/>
      <mass value="0.127087348341362"/>
      <inertia ixx="3.82011730423416E-05" ixy="-4.92358350897513E-08" ixz="4.89589432973119E-08" iyy="4.87048555222578E-05" iyz="6.70802942500512E-08" izz="4.10592077565559E-05"/>
    </inertial>
    <visual>
      <origin rpy="0 0 0" xyz="0 0 0"/>
      <geometry>
        <mesh filename="package://piper_description/meshes/dae/link4.dae"/>
      </geometry>
      <material name="">
        <color rgba="0.792156862745098 0.819607843137255 0.933333333333333 1"/>
      </material>
    </visual>
    <collision>
      <origin rpy="0 0 0" xyz="0 0 0"/>
      <geometry>
        <mesh filename="package://piper_description/meshes/link4.STL"/>
      </geometry>
    </collision>
  </link>
  <joint name="right/joint4" type="revolute">
    <origin rpy="-1.5708 0 1.3826" xyz="-0.24221 0.068514 0"/>
    <parent link="right/link3"/>
    <child link="right/link4"/>
    <axis xyz="0 0 1"/>
    <limit effort="100" lower="-1.832" upper="1.832" velocity="3"/>
  </joint>
  <link name="right/link5">
    <inertial>
      <origin rpy="0 0 0" xyz="8.82262433516967E-05 0.0566829014808256 -0.00196119720482461"/>
      <mass value="0.144711242639457"/>
      <inertia ixx="4.39644313662493E-05" ixy="-3.59259686444846E-08" ixz="-1.89747741386183E-08" iyy="5.63173920951307E-05" iyz="-2.1540716689785E-07" izz="4.88713664675268E-05"/>
    </inertial>
    <visual>
      <origin rpy="0 0 0" xyz="0 0 0"/>
      <geometry>
        <mesh filename="package://piper_description/meshes/dae/link5.dae"/>
      </geometry>
      <material name="">
        <color rgba="0.792156862745098 0.819607843137255 0.933333333333333 1"/>
      </material>
    </visual>
    <collision>
      <origin rpy="0 0 -3.14" xyz="0 0 0"/>
      <geometry>
        <mesh filename="package://piper_description/meshes/link5.STL"/>
      </geometry>
    </collision>
  </link>
  <joint name="right/joint5" type="revolute">
    <origin rpy="1.5708 0 0" xyz="0 0 0"/>
    <parent link="right/link4"/>
    <child link="right/link5"/>
    <axis xyz="0 0 1"/>
    <limit effort="100" lower="-1.22" upper="1.22" velocity="3"/>
  </joint>
  <link name="right/link6">
    <inertial>
      <origin rpy="0 0 0" xyz="0.00103120214523473 0.0121761387587524 0.0315480874960164"/>
      <mass value="0.195187143240719"/>
      <inertia ixx="6.43790256535539E-05" ixy="-1.2366166157046E-06" ixz="1.97664606328472E-07" iyy="0.000126146396374301" iyz="2.41157078516408E-06" izz="0.000154087076816444"/>
    </inertial>
    <visual>
      <origin rpy="-1.57 0 0" xyz="-0.002 -0.008 0"/>
      <geometry>
        <mesh filename="package://piper_description/meshes/dae/camera_v3.dae"/>
      </geometry>
      <material name="">
        <color rgba="0.792156862745098 0.819607843137255 0.933333333333333 1"/>
      </material>
    </visual>
    <collision>
      <origin rpy="-1.57 0 0" xyz="-0.002 -0.008 0"/>
      <geometry>
        <mesh filename="package://piper_description/meshes/dae/camera_v3.dae"/>
      </geometry>
    </collision>
  </link>
  <joint name="right/joint6" type="revolute">
    <origin rpy="-1.5708 -1.5708 0" xyz="0 0.091 0.0014165"/>
    <parent link="right/link5"/>
    <child link="right/link6"/>
    <axis xyz="0 0 1"/>
    <limit effort="100" lower="-3.14" upper="3.14" velocity="3"/>
  </joint>
  <link name="right/link7">
    <inertial>
      <origin rpy="0 0 0" xyz="-0.000277778383727112 -0.0467673043650824 -0.00921029491873201"/>
      <mass value="0.02648229234527"/>
      <inertia ixx="9.99787479924589E-06" ixy="-1.57548495096104E-07" ixz="-2.71342775003487E-08" iyy="6.1795212293655E-06" iyz="-1.58939803580081E-06" izz="1.42102717246564E-05"/>
    </inertial>
    <visual>
      <origin rpy="0 0 0" xyz="0 0 0"/>
      <geometry>
        <mesh filename="package://piper_description/meshes/dae/link7.dae"/>
      </geometry>
      <material name="">
        <color rgba="0.792156862745098 0.819607843137255 0.933333333333333 1"/>
      </material>
    </visual>
    <collision>
      <origin rpy="0 3.14 0" xyz="-0.001 0 0.0003"/>
      <geometry>
        <mesh filename="package://piper_description/meshes/link7.STL"/>
      </geometry>
    </collision>
  </link>
  <joint name="right/joint7" type="prismatic">
    <origin rpy="1.5708 0 1.5708" xyz="0 0 0.13503"/>
    <parent link="right/link6"/>
    <child link="right/link7"/>
    <axis xyz="0 0 -1"/>
    <limit effort="10" lower="0" upper="0.05" velocity="1"/>
  </joint>
  <link name="right/link8">
    <inertial>
      <origin rpy="0 0 0" xyz="0.000277816920932317 0.0467673824063769 -0.00921030054508036"/>
      <mass value="0.0264822021416248"/>
      <inertia ixx="9.99779119357223E-06" ixy="-1.57542283433504E-07" ixz="2.71367446701359E-08" iyy="6.17952441557932E-06" iyz="1.58939319453383E-06" izz="1.4210192754512E-05"/>
    </inertial>
    <visual>
      <origin rpy="0 0 0" xyz="0 0 0"/>
      <geometry>
        <mesh filename="package://piper_description/meshes/dae/link8.dae"/>
      </geometry>
      <material name="">
        <color rgba="0.792156862745098 0.819607843137255 0.933333333333333 1"/>
      </material>
    </visual>
    <collision>
      <origin rpy="3.14 0 0" xyz="-0.001 0 0.0003"/>
      <geometry>
        <mesh filename="package://piper_description/meshes/link8.STL"/>
      </geometry>
    </collision>
  </link>
  <joint name="right/joint8" type="prismatic">
    <origin rpy="-1.5708 0 1.5708" xyz="0 0 0.13503"/>
    <parent link="right/link6"/>
    <child link="right/link8"/>
    <axis xyz="0 0 1"/>
    <limit effort="10" lower="-0.05" upper="0" velocity="1"/>
  </joint>
  <joint name="arm_and_lifting_left" type="fixed">
    <origin rpy="0.0 0.0 0.0" xyz="0.144 0.306 0.138"/>
    <parent link="lifting_link"/>
    <child link="left/arm_base"/>
    <axis xyz="0.0 0.0 0.0"/>
    <limit effort="0.0" lower="0.0" upper="0.0" velocity="0.0"/>
  </joint>
  <joint name="arm_and_lifting_right" type="fixed">
    <origin rpy="0.0 0.0 0.0" xyz="0.144 -0.306 0.138"/>
    <parent link="lifting_link"/>
    <child link="right/arm_base"/>
    <axis xyz="0.0 0.0 0.0"/>
    <limit effort="0.0" lower="0.0" upper="0.0" velocity="0.0"/>
  </joint>
</robot>

